Workbook

Sheet Inputs
A1: Chathura Printers - Inputs (all amounts in Rs.)
A2: Legend: blue text = input you can change; black = formula. Change blue cells and every sheet updates.
A4: Loan
A5: Loan amount (Rs.) | B5: 2800000 | C5: Rs. 28 lakh - from you
A6: Annual interest rate | B6: 0.155 | C6: 15.5% - from you; confirm with bank if fixed or floating
A7: Term (years) | B7: 5 | C7: 5 years - from you
A8: Monthly installment (EMI) | B8: =PMT(B6/12,B7*12,-B5) | C8: Standard reducing-balance loan; check 'What''s Left at Month End' for bank verification
A9: Working days per month | B9: 26 | C9: Assumption
A11: Fixed monthly expenses
A12: Manager salary | B12: 50000 | C12: Assumption - replace with the salary you agree
A13: Employer EPF + ETF rate | B13: 0.15 | C13: 12% EPF + 3% ETF on salary
A14: Electricity | B14: 18000 | C14: Assumption - production machines use a lot of power
A15: Machine repairs & servicing | B15: 8000 | C15: Assumption
A16: Marketing | B16: 5000 | C16: Assumption
A17: Phone & internet | B17: 4000 | C17: Assumption
A18: Shop rent and licences/insurance/misc. removed as per your instruction (set to 0).
A20: Sample work per month
A21: Work | B21: Volume / month | C21: Unit | D21: Selling price per unit (Rs.) | E21: Direct cost per unit (Rs.) | F21: Notes
A22: Photocopy (double-sided sheet) | B22: 20000 | C22: sheets | D22: 4 | E22: 3.2 | F22: Rs. 4 price from you. Cost = paper ~2.40 + toner/servicing ~0.80 (assumption)
A23: Bill books | B23: 100 | C23: books | D23: 1800 | E23: 1100 | F23: Assumption: NCR paper, numbering, binding, labour
A24: Posters (A3 colour) | B24: 600 | C24: posters | D24: 200 | E24: 90 | F24: Assumption
A25: Other (cards, flyers, lamination) | B25: 1 | C25: lump sum | D25: 80000 | E25: 48000 | F25: Assumption: 40% margin

Sheet What's Left at Month End
A1: Chathura Printers — What’s Left at Month End & Bank Loan Calculator
A2: Legend: Blue bold numbers = editable inputs you can change; Black = formula calculated; Green = verified/confirmed status.
A4: EXECUTIVE SUMMARY (Sample Month at Rs. 460,000 Revenue)
A5: Monthly Revenue | C5: Fixed Expenses | D5: Monthly Loan Installment | E5: Left to Reinvest (Surplus) | F5: Break-Even Monthly Rev.
A6: =C36 | C6: =B29 | D6: =B20 | E6: =C42 | F6: =C44
A8: 1. FIXED PERSONAL LOAN CALCULATOR & BANK CONFIRMATION
A9: Loan Parameter (Inputs) | B9: Your Value | C9: Notes / Assumptions | D9: Calculated Metric | E9: Formula Result (Rs.) | F9: Calculation Details
A10: Loan principal amount (Rs.) | B10: 2800000 | C10: Rs. 28 lakh principal (change as needed) | D10: Monthly installment (Reducing EMI) | E10: =PMT(B11/12,B13,-B10) | F10: Standard bank reducing balance payment
A11: Annual fixed interest rate | B11: 0.155 | C11: 15.5% fixed interest rate per annum | D11: Month 1 interest amount | E11: =B10*(B11/12) | F11: First month interest portion (= P × r / 12)
A12: Loan term (years) | B12: 5 | C12: 5 years period | D12: Average monthly interest | E12: =(E14-B10)/B13 | F12: Average interest per month over tenure
A13: Loan term (months) | B13: =B12*12 | C13: =Years × 12 months | D13: Total interest paid over term | E13: =E14-B10 | F13: Total interest cost across entire 5 years
A14: Working days per month | B14: 26 | C14: 26 working days (Sri Lanka printing shop) | D14: Total loan repayment over term | E14: =E10*B13 | F14: Total money paid to bank (Principal + Interest)
A15: Flat Rate Alternative: Total Interest | B15: =B10*B11*B12 | C15: =Principal × Rate × Years (Flat method) | D15: Flat Rate: Monthly Installment | E15: =(B10+B15)/B13 | F15: Installment if bank uses flat rate instead of EMI
A17: BANK QUOTE CONFIRMATION & VERIFICATION
A18: Bank Quoted Monthly Installment (Rs.) | B18: 67350 | C18: Enter the exact monthly installment quoted by your bank manager | D18: Installment Variance vs Calculated EMI | E18: =B18-E10 | F18: =Bank Quote − Calculated Reducing EMI (Goal is ~Rs. 0)
A19: Bank Quoted Monthly Interest Amount (Rs.) | B19: 36167 | C19: Optional: Month 1 interest quoted by bank (matches ~Rs. 36,167) | D19: Interest Variance vs Month 1 Interest | E19: =IF(B19=0,0,B19-E11) | F19: =Bank Quote − Month 1 Interest (P × r / 12)
A20: Active Loan Installment Used in Cash Flow | B20: =IF(B18>0,B18,E10) | C20: Uses confirmed bank quote (or calculated EMI if blank) | D20: Confirmation Status | E20: =IF(B18=0,"Enter Bank Quote",IF(ABS(E18)<=10,"CONFIRMED: MATCHES BANK QUOTE",IF(ABS(B18-E15)<=10,"MATCHES FLAT RATE QUOTE",IF(E18>0,"BANK QUOTE IS HIGHER","BANK QUOTE IS LOWER"))))
A22: 2. FIXED MONTHLY EXPENSES (Updated: No Rent, No Licences/Insurance)
A23: Expense Item | B23: Amount (Rs.) | C23: Details / Breakdown | D23: Category / Notes
A24: Manager salary (Rs. 50,000 basic + EPF/ETF Rs. 7,500) | B24: 57500 | C24: 12% EPF (Rs. 6,000) + 3% ETF (Rs. 1,500) on Rs. 50k | D24: Payroll / Staff
A25: Electricity | B25: 18000 | C25: Heavy production machinery power consumption | D25: Utilities
A26: Machine repairs and servicing | B26: 8000 | C26: Preventive maintenance, drum & blade replacement | D26: Maintenance
A27: Marketing | B27: 5000 | C27: Flyers, local social media promos, customer canvassing | D27: Sales / Promo
A28: Phone and internet | B28: 4000 | C28: High-speed broadband for customer file uploads + phone line | D28: Communications
A29: Total Fixed Monthly Expenses | B29: =SUM(B24:B28) | C29: Strict fixed overhead (Rent & Licences set to Rs. 0 as instructed) | D29: Operational Overhead Base
A32: 3. WHAT’S LEFT AT MONTH END (Revenue Scenarios & Custom Planner)
A34: Financial Metric / Cash Flow Step | B34: Slow Month | C34: Sample Month | D34: Busy Month | E34: Custom Target | F34: Formula Logic / Strategic Meaning
A35: Sales Volume Level | B35: Rs. 300,000 / mo | C35: Rs. 460,000 / mo | D35: Rs. 600,000 / mo | E35: Editable Goal | F35: Scenarios comparison for owner decision making
A36: Monthly revenue | B36: 300000 | C36: 460000 | D36: 600000 | E36: 500000 | F36: Gross sales generated in the calendar month
A37: Gross profit margin (%) | B37: ='Monthly Plan'!$F$8 | C37: ='Monthly Plan'!$F$8 | D37: ='Monthly Plan'!$F$8 | E37: ='Monthly Plan'!$F$8 | F37: Overall direct product margin (40.0% from print jobs)
A38: Gross profit (Rs.) | B38: =B36*B37 | C38: =C36*C37 | D38: =D36*D37 | E38: =E36*E37 | F38: =Monthly Revenue × Gross Margin (40%)
A39: Less: Fixed expenses (Rs.) | B39: =-$B$29 | C39: =-$B$29 | D39: =-$B$29 | E39: =-$B$29 | F39: Manager salary + Electricity + Repairs + Promo + Phone
A40: Operating profit (Rs.) | B40: =B38+B39 | C40: =C38+C39 | D40: =D38+D39 | E40: =E38+E39 | F40: Operating profit before debt service (= Gross Profit − Overhead)
A41: Less: Loan installment (Rs.) | B41: =-$B$20 | C41: =-$B$20 | D41: =-$B$20 | E41: =-$B$20 | F41: Fixed monthly bank loan installment (confirmed with bank)
A42: Left to reinvest in business (Rs.) | B42: =B40+B41 | C42: =C40+C41 | D42: =D40+D41 | E42: =E40+E41 | F42: NET SURPLUS (Positive = reinvest/savings; Negative = top-up)
A43: Cash flow status for owner | B43: =IF(B42>=0,"SURPLUS: Covers loan + manager","DEFICIT: Top-up from personal salary") | C43: =IF(C42>=0,"SURPLUS: Covers loan + manager","DEFICIT: Top-up from personal salary") | D43: =IF(D42>=0,"SURPLUS: Covers loan + manager","DEFICIT: Top-up from personal salary") | E43: =IF(E42>=0,"SURPLUS: Covers loan + manager","DEFICIT: Top-up from personal salary") | F43: Owner cash security assessment
A44: Break-even monthly revenue (Rs.) | B44: =($B$29+$B$20)/B37 | C44: =($B$29+$B$20)/C37 | D44: =($B$29+$B$20)/D37 | E44: =($B$29+$B$20)/E37 | F44: =(Fixed Expenses + Loan Installment) / Gross Margin
A45: Break-even revenue per working day | B45: =B44/$B$14 | C45: =C44/$B$14 | D45: =D44/$B$14 | E45: =E44/$B$14 | F45: =Break-even monthly revenue / 26 working days
A47: OWNER SUMMARY & RISK MANAGEMENT GUIDELINES:
A48: 1. Break-even threshold is ~Rs. 400,000 / month (~Rs. 15,385 / day across 26 working days). Any sales above this directly build business cash reserve.
...

Sheet Monthly Plan
A1: Sample Month - Profit Plan (Rs.)
A3: Work | B3: Volume | C3: Revenue | D3: Direct cost | E3: Gross profit | F3: Margin
A4: =Inputs!A22 | B4: =Inputs!B22 | C4: =Inputs!B22*Inputs!D22 | D4: =Inputs!B22*Inputs!E22 | E4: =C4-D4 | F4: =IF(C4=0,0,E4/C4)
A5: =Inputs!A23 | B5: =Inputs!B23 | C5: =Inputs!B23*Inputs!D23 | D5: =Inputs!B23*Inputs!E23 | E5: =C5-D5 | F5: =IF(C5=0,0,E5/C5)
A6: =Inputs!A24 | B6: =Inputs!B24 | C6: =Inputs!B24*Inputs!D24 | D6: =Inputs!B24*Inputs!E24 | E6: =C6-D6 | F6: =IF(C6=0,0,E6/C6)
A7: =Inputs!A25 | B7: =Inputs!B25 | C7: =Inputs!B25*Inputs!D25 | D7: =Inputs!B25*Inputs!E25 | E7: =C7-D7 | F7: =IF(C7=0,0,E7/C7)
A8: Total | C8: =SUM(C4:C7) | D8: =SUM(D4:D7) | E8: =SUM(E4:E7) | F8: =IF(C8=0,0,E8/C8)
A10: Fixed monthly expenses
A11: Manager salary | B11: =Inputs!B12
A12: Employer EPF + ETF | B12: =Inputs!B12*Inputs!B13
A13: Electricity | B13: =Inputs!B14
A14: Machine repairs & servicing | B14: =Inputs!B15
A15: Marketing | B15: =Inputs!B16
A16: Phone & internet | B16: =Inputs!B17
A17: Total fixed expenses | B17: =SUM(B11:B16)
A19: Month-end result
A20: Gross profit | B20: =E8
A21: Less: fixed expenses | B21: =-B17
A22: Operating profit | B22: =B20+B21
A23: Less: loan installment | B23: =-'What''s Left at Month End'!$B$20
A24: Left to reinvest in the business | B24: =B22+B23
A26: Break-even
A27: Break-even monthly revenue (fixed + loan) | B27: =IF(F8=0,0,(B17+'What''s Left at Month End'!$B$20)/F8)
A28: Break-even revenue per working day | B28: =B27/Inputs!B9
A29: Current sample revenue per working day | B29: =C8/Inputs!B9
A30: Note: break-even assumes the same overall margin as the sample month.

Sheet Scenarios
A1: Revenue Scenarios (Rs. per month)
A2: Change the blue revenue cells to test other months. Margin is taken from the Monthly Plan sheet.
B4: Slow month | C4: Sample month | D4: Busy month
A5: Monthly revenue | B5: 300000 | C5: 460000 | D5: 600000
A6: Gross margin | B6: ='Monthly Plan'!$F$8 | C6: ='Monthly Plan'!$F$8 | D6: ='Monthly Plan'!$F$8
A7: Gross profit | B7: =B5*B6 | C7: =C5*C6 | D7: =D5*D6
A8: Fixed expenses | B8: =-'Monthly Plan'!$B$17 | C8: =-'Monthly Plan'!$B$17 | D8: =-'Monthly Plan'!$B$17
A9: Operating profit | B9: =B7+B8 | C9: =C7+C8 | D9: =D7+D8
A10: Loan installment | B10: =-'What''s Left at Month End'!$B$20 | C10: =-'What''s Left at Month End'!$B$20 | D10: =-'What''s Left at Month End'!$B$20
A11: Left to reinvest (negative = top up from salary) | B11: =B9+B10 | C11: =C9+C10 | D11: =D9+D10
A13: Break-even monthly revenue | B13: ='Monthly Plan'!B27

Sheet Loan Models
A1: Loan Models Compared
A2: Blue = editable. Rates assumed equal to your 15.5% unless you change them.
A4: Model | B4: Loan amount (Rs.) | C4: Rate | D4: Years | E4: Monthly payment | F4: Total repaid | G4: Total interest | H4: Notes
A5: 5 years, standard (your plan) | B5: =Inputs!B5 | C5: =Inputs!B6 | D5: =Inputs!B7 | E5: =PMT(C5/12,D5*12,-B5) | F5: =E5*D5*12 | G5: =F5-B5 | H5: Cheapest overall interest, tight cash flow
A6: 7 years | B6: =Inputs!B5 | C6: =Inputs!B6 | D6: 7 | E6: =PMT(C6/12,D6*12,-B6) | F6: =E6*D6*12 | G6: =F6-B6 | H6: Lower monthly burden, more total interest
A7: Rs. 20 lakh loan + Rs. 8 lakh own money | B7: 2000000 | C7: =Inputs!B6 | D7: 5 | E7: =PMT(C7/12,D7*12,-B7) | F7: =E7*D7*12 | G7: =F7-B7 | H7: Lowest risk if you can fund Rs. 8 lakh yourself
A9: Interest-only start (grace period)
A10: Loan amount (Rs.) | B10: =Inputs!B5
A11: Monthly interest-only payment | B11: =B10*Inputs!B6/12
A12: Ask the bank if a 3-6 month interest-only start is possible while machines arrive and sales build up.
A14: Also ask the bank: is the rate fixed or floating? Any SME/machinery-financing scheme or hire purchase option? (verify current terms)
